<!--# Created by Xinchao Song on June 30, 2019.-->

<mujoco model="The 1-D Bump Model">
    <!--Some parameters may still need to be tuned properly.-->

    <compiler angle="radian"/>
    <option>
        <flag gravity="disable"/>
    </option>

    <asset>
        <include file="gripah_asset.xml"/>
        <mesh name="mesh:bump" file="objects/bump_80_mujoco.STL"/>
        <texture name="tex:floor" type="2d" builtin="checker" rgb1="1 1 1" rgb2="0 0 0" width="100" height="100"
                 mark="cross"/>
        <material name="mat:floor" reflectance="0.1" texture="tex:floor" texrepeat="60 60"/>
    </asset>

    <default>
        <joint armature="1" damping="1"/>
        <geom contype="1" condim="3" friction="1 0.1 0.1"/>

        <default class="slider">
            <joint type="slide" axis="1 0 0"/>
        </default>

        <default class="bump">
            <geom type="mesh" mesh="mesh:bump" mass="0.45" quat="1 1 0 0"/>
        </default>
    </default>

    <worldbody>
        <light name="light" directional="true" diffuse="0.8 0.8 0.8" specular="0.4 0.4 0.4" pos="0 -10 20"
               dir="0 1 -1"/>
        <geom name="floor" type="plane" material="mat:floor" size="240 240 240" pos="0 0 0" rgba="0.752 0.752 0.752 1"
              quat="1 0 0 0"/>

        <include file="gripah_body.xml"/>

        <body name="bump1" pos="0 0 0">
            <geom name="bump1" rgba="1 0 0 1" class="bump"/>
            <joint name="slide:bump1" class="slider"/>
        </body>

        <body name="bump2" pos="0 0 0">
            <geom name="bump2" rgba="0 0 1 1" class="bump"/>
            <joint name="slide:bump2" class="slider"/>
        </body>
        <site name="world-left-end" size="1" pos="0 0 0" rgba="1 0 1 0.3" type="sphere"/>
        <site name="world-center" size="1" pos="40 0 0" rgba="1 0 1 0.3" type="sphere"/>
        <site name="world-right-end" size="1" pos="80 0 0" rgba="1 0 1 0.3" type="sphere"/>
    </worldbody>

    <actuator>
        <!--Need to be consistent with the wrapper.-->
        <velocity name="velocity:x" joint="slide:gripah-base-x" gear="1" kv="100"/>
        <velocity name="velocity:narrow-finger" joint="hinge:narrow-finger" gear="1" kv="100"/>
        <position name="position:narrow-finger" joint="hinge:narrow-finger" gear="1" kp="100"/>
    </actuator>

    <sensor>
        <framepos name="sensor:gripah-center" objtype="site" objname="gripah-center"/>
    </sensor>
</mujoco>
